Workbook

Sheet Read me
A1: The Reimbursement Playbook — working template (Hubricon)
A3: What this is: one sheet per Amazon report, a Claims sheet that dates and values every claim, and a filing log.
A4: Every window and approval assumption on the Windows sheet is the same constant Hubricon's engine runs; change a cell there and every claim recalculates.
A6: How to use it:
A7: 1. Windows: set 'As of' to today (it is =TODAY() by default).
A8: 2. COGS: paste your landed cost per SKU (unit cost + inbound freight + packaging). Claims are valued at landed cost; Amazon reimburses at manufacturing cost.
A9: 3. Ledger / Returns / Reimbursements / Refunds: paste the raw exports. The helper columns on the right classify each row.
A10: 4. Claims: one row per loss you are filing. Type, SKU, event date and units are yours; everything else is a formula.
A11: 5. Filing log: the case id, the date filed, what Amazon paid, and whether it paid in cash or in kind.
A13: The rows already here are demo data from a fictional catalogue (Tarnhollow). Delete them before you paste your own.
A14: Inbound-shipment shortages are not in this playbook: they need the shipment reconciliation export.
A16: Free training and the written playbook: https://www.hubricon.com/learn/reimbursement-playbook

Sheet Windows
A1: Setting | B1: Value | C1: What it means | D1: Source
A2: as_of | B2: =TODAY() | C2: The date every claim is judged against; the demo rows were judged as of 2026-09-01 | D2: you
A3: warehouse_eligible_after_days | B3: 30 | C3: Days after a warehouse loss or damage before you may file | D3: hubricon_engine.models.recovery
A4: warehouse_deadline_days | B4: 60 | C4: Days after a warehouse loss or damage until the window shuts | D4: hubricon_engine.models.recovery
A5: refund_min_age_days | B5: 45 | C5: A refund younger than this is not a claim yet | D5: hubricon_engine.models.recovery
A6: refund_eligible_after_days | B6: 60 | C6: Days after a refund before a no-return claim may be filed | D6: hubricon_engine.models.recovery
A7: refund_deadline_days | B7: 120 | C7: Days after a refund until the no-return window shuts | D7: hubricon_engine.models.recovery
A8: damaged_return_deadline_days | B8: 60 | C8: Days after a damaged return until the window shuts | D8: hubricon_engine.models.recovery
A9: expiring_within_days | B9: 14 | C9: A claim this close to its deadline is called expiring | D9: hubricon_engine.models.recovery
A10: found_match_window_days | B10: 45 | C10: A 'found' adjustment inside this many days offsets a loss | D10: hubricon_engine.models.recovery
A11: reimbursement_match_window_days | B11: 90 | C11: A paid reimbursement inside this many days offsets a loss | D11: hubricon_engine.models.recovery
A12: no_cost_value_fraction | B12: 0.5 | C12: Value fallback when no landed cost is on file, as a share of price | D12: hubricon_engine.models.recovery
A14: Claim type | B14: P(approve) | C14: What it means | D14: Source
A15: warehouse_lost | B15: 0.85 | C15: Stated assumption used for expected value; Amazon's own unreconciled counts approve more often | D15: hubricon_engine.models.recovery.P_APPROVE
A16: warehouse_damaged | B16: 0.85 | C16: Stated assumption used for expected value; Amazon's own unreconciled counts approve more often | D16: hubricon_engine.models.recovery.P_APPROVE
A17: carrier_damaged | B17: 0.7 | C17: Stated assumption used for expected value; Amazon's own unreconciled counts approve more often | D17: hubricon_engine.models.recovery.P_APPROVE
A18: transit_lost | B18: 0.7 | C18: Stated assumption used for expected value; Amazon's own unreconciled counts approve more often | D18: hubricon_engine.models.recovery.P_APPROVE
A19: refund_no_return | B19: 0.7 | C19: Stated assumption used for expected value; Amazon's own unreconciled counts approve more often | D19: hubricon_engine.models.recovery.P_APPROVE
A20: damaged_return | B20: 0.6 | C20: Stated assumption used for expected value; Amazon's own unreconciled counts approve more often | D20: hubricon_engine.models.recovery.P_APPROVE
A21: reimbursement_reversal | B21: 0.5 | C21: Stated assumption used for expected value; Amazon's own unreconciled counts approve more often | D21: hubricon_engine.models.recovery.P_APPROVE
A23: Claim type | B23: Eligible after (days) | C23: Deadline (days) | D23: Counted from
A24: warehouse_lost | B24: 30 | C24: 60 | D24: the adjustment date
A25: warehouse_damaged | B25: 30 | C25: 60 | D25: the adjustment date
A26: carrier_damaged | B26: 30 | C26: 60 | D26: the adjustment date
A27: transit_lost | B27: 30 | C27: 60 | D27: the adjustment date
A28: refund_no_return | B28: 60 | C28: 120 | D28: the refund date
A29: damaged_return | B29: 0 | C29: 60 | D29: the return date
A30: reimbursement_reversal | B30: 0 | C30: 60 | D30: the reversal date
A32: TYPE_TABLE_ROW | B32: 24

Sheet Reason codes
A1: Ledger reason | B1: Class | C1: Claimable?
A2: 5 | B2: found | C2: no
A3: 6 | B3: transit_lost | C3: yes
A4: D | B4: warehouse_damaged | C4: yes
A5: E | B5: customer_damaged | C5: no
A6: F | B6: found | C6: no
A7: H | B7: carrier_damaged | C7: yes
A8: K | B8: carrier_damaged | C8: yes
A9: M | B9: warehouse_lost | C9: yes
A10: N | B10: warehouse_lost | C10: yes
A11: O | B11: transfer | C11: no
A12: P | B12: disposed | C12: no
... A15: X | B15: transfer | C15: no

Sheet COGS
A1: sku | B1: product_name | C1: unit_cost_usd | D1: inbound_freight_per_unit_usd | E1: packaging_per_unit_usd | F1: other_cost_per_unit_usd | G1: landed_cost (formula)
A2: TH-APRWAX-21 | B2: Apron Waxed Canvas | C2: 9.6 | D2: 0.6 | E2: 0.4 | F2: 0 | G2: =SUM(C2:F2)
A3: TH-BAMCUT-05 | B3: Bamboo Cutting Board L | C3: 6.1 | D3: 1.4 | E3: 0.4 | F3: 0 | G3: =SUM(C3:F3)
A4: TH-BAMCUT-06 | B4: Bamboo Cutting Board M | C4: 4.2 | D4: 1 | E4: 0.3 | F4: 0 | G4: =SUM(C4:F4)
A5: TH-BREKNI-10 | B5: Bread Knife 10in | C5: 6.8 | D5: 0.7 | E5: 0.5 | F5: 0 | G5: =SUM(C5:F5)
A6: TH-CARSTE-04 | B6: Carbon Steel Wok | C6: 13.2 | D6: 2.3 | E6: 0.6 | F6: 0 | G6: =SUM(C6:F6)
A7: TH-CASIRO-01 | B7: Cast Iron Skillet 10in | C7: 9.4 | D7: 2.1 | E7: 0.6 | F7: 0 | G7: =SUM(C7:F7)
A8: TH-CASIRO-02 | B8: Cast Iron Skillet 12in | C8: 12.8 | D8: 2.6 | E8: 0.7 | F8: 0 | G8: =SUM(C8:F8)
A9: TH-CHEKNI-08 | B9: Chef Knife 8in | C9: 14.6 | D9: 1.1 | E9: 0.9 | F9: 0 | G9: =SUM(C9:F9)
A10: TH-COFCAN-19 | B10: Coffee Canister Airtight | C10: 5 | D10: 0.8 | E10: 0.4 | F10: 0 | G10: =SUM(C10:F10)
A11: TH-ENADUT-03 | B11: Enamel Dutch Oven 5qt | C11: 24.5 | D11: 4.2 | E11: 1.1 | F11: 0 | G11: =SUM(C11:F11)
A12: TH-FREPRE-17 | B12: French Press 34oz | C12: 7.1 | D12: 1.3 | E12: 0.6 | F12: 0 | G12: =SUM(C12:F12)
A13: TH-KITTOW-24 | B13: Kitchen Towels Linen 4pk | C13: 5.5 | D13: 0.5 | E13: 0.3 | F13: 0 | G13: =SUM(C13:F13)
... A25: TH-WALSER-07 | B25: Walnut Serving Tray | C25: 10.9 | D25: 1.7 | E25: 0.5 | F25: 0 | G25: =SUM(C25:F25)

Sheet Ledger
A1: Date | B1: FNSKU | C1: ASIN | D1: MSKU | E1: Title | F1: Event Type | G1: Reference ID | H1: Quantity | I1: Fulfillment Center | J1: Disposition | K1: Reason | L1: Country | M1: Reconciled Quantity | N1: Unreconciled Quantity | O1: Class (helper) | P1: Claimable (helper) | Q1: Units lost (helper)
A2: 2026-02-20 | B2: X0TH0012 | C2: B0TH012KX | D2: TH-STAMIX-12 | E2: Stainless Mixing Bowls 5pc | F2: Receipts | G2: FBA15TH77123 | H2: 495 | I2: MDW2 | J2: SELLABLE | L2: US | M2: 0 | N2: 0 | O2: =IFERROR(VLOOKUP(K2,'Reason codes'!$A$2:$B$40,2,FALSE),"") | P2: =IF(AND(ISNUMBER(SEARCH("adjust",F2)),OR(O2="warehouse_lost",O2="warehouse_damaged",O2="carrier_damaged",O2="transit_lost")),"yes","no") | Q2: =IF(P2="yes",IF(N2<>"",N2,MAX(0,-H2)),0)
A3: 2026-02-20 | B3: X0TH0020 | C3: B0TH020KX | D3: TH-TEAINF-20 | E3: Tea Infuser Mug | F3: Receipts | G3: FBA15TH77209 | H3: 570 | I3: PHX7 | J3: SELLABLE | L3: US | M3: 0 | N3: 0 | O3: =IFERROR(VLOOKUP(K3,'Reason codes'!$A$2:$B$40,2,FALSE),"") | P3: =IF(AND(ISNUMBER(SEARCH("adjust",F3)),OR(O3="warehouse_lost",O3="warehouse_damaged",O3="carrier_damaged",O3="transit_lost")),"yes","no") | Q3: =IF(P3="yes",IF(N3<>"",N3,MAX(0,-H3)),0)
A4: 2026-02-24 | B4: X0TH0005 | C4: B0TH005KX | D4: TH-BAMCUT-05 | E4: Bamboo Cutting Board L | F4: Receipts | G4: FBA15TH77047 | H4: 810 | I4: DFW6 | J4: SELLABLE | L4: US | M4: 0 | N4: 0 | O4: =IFERROR(VLOOKUP(K4,'Reason codes'!$A$2:$B$40,2,FALSE),"") | P4: =IF(AND(ISNUMBER(SEARCH("adjust",F4)),OR(O4="warehouse_lost",O4="warehouse_damaged",O4="carrier_damaged",O4="transit_lost")),"yes","no") | Q4: =IF(P4="yes",IF(N4<>"",N4,MAX(0,-H4)),0)
A5: 2026-03-05 | B5: X0TH0014 | C5: B0TH014KX | D5: TH-MEACUP-14 | E5: Measuring Cups Steel | F5: Receipts | G5: FBA15TH77146 | H5: 705 | I5: DFW6 | J5: SELLABLE | L5: US | M5: 0 | N5: 0 | O5: =IFERROR(VLOOKUP(K5,'Reason codes'!$A$2:$B$40,2,FALSE),"") | P5: =IF(AND(ISNUMBER(SEARCH("adjust",F5)),OR(O5="warehouse_lost",O5="warehouse_damaged",O5="carrier_damaged",O5="transit_lost")),"yes","no") | Q5: =IF(P5="yes",IF(N5<>"",N5,MAX(0,-H5)),0)
A6: 2026-03-11 | B6: X0TH0006 | C6: B0TH006KX | D6: TH-BAMCUT-06 | E6: Bamboo Cutting Board M | F6: Receipts | G6: FBA15TH77055 | H6: 1080 | I6: LAX9 | J6: SELLABLE | L6: US | M6: 0 | N6: 0 | O6: =IFERROR(VLOOKUP(K6,'Reason codes'!$A$2:$B$40,2,FALSE),"") | P6: =IF(AND(ISNUMBER(SEARCH("adjust",F6)),OR(O6="warehouse_lost",O6="warehouse_damaged",O6="carrier_damaged",O6="transit_lost")),"yes","no") | Q6: =IF(P6="yes",IF(N6<>"",N6,MAX(0,-H6)),0)
A7: 2026-03-15 | B7: X0TH0014 | C7: B0TH014KX | D7: TH-MEACUP-14 | E7: Measuring Cups Steel | F7: Receipts | G7: FBA15TH77145 | H7: 705 | I7: PHX7 | J7: SELLABLE | L7: US | M7: 0 | N7: 0 | O7: =IFERROR(VLOOKUP(K7,'Reason codes'!$A$2:$B$40,2,FALSE),"") | P7: =IF(AND(ISNUMBER(SEARCH("adjust",F7)),OR(O7="warehouse_lost",O7="warehouse_damaged",O7="carrier_damaged",O7="transit_lost")),"yes","no") | Q7: =IF(P7="yes",IF(N7<>"",N7,MAX(0,-H7)),0)
A8: 2026-03-22 | B8: X0TH0023 | C8: B0TH023KX | D8: TH-TRICOR-23 | E8: Trivet Cork Set | F8: Receipts | G8: FBA15TH77243 | H8: 915 | I8: ONT8 | J8: SELLABLE | L8: US | M8: 0 | N8: 0 | O8: =IFERROR(VLOOKUP(K8,'Reason codes'!$A$2:$B$40,2,FALSE),"") | P8: =IF(AND(ISNUMBER(SEARCH("adjust",F8)),OR(O8="warehouse_lost",O8="warehouse_damaged",O8="carrier_damaged",O8="transit_lost")),"yes","no") | Q8: =IF(P8="yes",IF(N8<>"",N8,MAX(0,-H8)),0)
A9: 2026-03-23 | B9: X0TH0002 | C9: B0TH002KX | D9: TH-CASIRO-02 | E9: Cast Iron Skillet 12in | F9: Receipts | G9: FBA15TH77010 | H9: 615 | I9: LAX9 | J9: SELLABLE | L9: US | M9: 0 | N9: 0 | O9: =IFERROR(VLOOKUP(K9,'Reason codes'!$A$2:$B$40,2,FALSE),"") | P9: =IF(AND(ISNUMBER(SEARCH("adjust",F9)),OR(O9="warehouse_lost",O9="warehouse_damaged",O9="carrier_damaged",O9="transit_lost")),"yes","no") | Q9: =IF(P9="yes",IF(N9<>"",N9,MAX(0,-H9)),0)
A10: 2026-03-23 | B10: X0TH0011 | C10: B0TH011KX | D10: TH-KNISHA-11 | E10: Knife Sharpener Whetstone | F10: Receipts | G10: FBA15TH77108 | H10: 570 | I10: LAX9 | J10: SELLABLE | L10: US | M10: 0 | N10: 0 | O10: =IFERROR(VLOOKUP(K10,'Reason codes'!$A$2:$B$40,2,FALSE),"") | P10: =IF(AND(ISNUMBER(SEARCH("adjust",F10)),OR(O10="warehouse_lost",O10="warehouse_damaged",O10="carrier_damaged",O10="transit_lost")),"yes","no") | Q10: =IF(P10="yes",IF(N10<>"",N10,MAX(0,-H10)),0)
A11: 2026-03-26 | B11: X0TH0013 | C11: B0TH013KX | D11: TH-SILSPA-13 | E11: Silicone Spatula Set | F11: Receipts | G11: FBA15TH77135 | H11: 1350 | I11: PHX7 | J11: SELLABLE | L11: US | M11: 0 | N11: 0 | O11: =IFERROR(VLOOKUP(K11,'Reason codes'!$A$2:$B$40,2,FALSE),"") | P11: =IF(AND(ISNUMBER(SEARCH("adjust",F11)),OR(O11="warehouse_lost",O11="warehouse_damaged",O11="carrier_damaged",O11="transit_lost")),"yes","no") | Q11: =IF(P11="yes",IF(N11<>"",N11,MAX(0,-H11)),0)
A12: 2026-03-27 | B12: X0TH0003 | C12: B0TH003KX | D12: TH-ENADUT-03 | E12: Enamel Dutch Oven 5qt | F12: Receipts | G12: FBA15TH77025 | H12: 390 | I12: LAX9 | J12: SELLABLE | L12: US | M12: 0 | N12: 0 | O12: =IFERROR(VLOOKUP(K12,'Reason codes'!$A$2:$B$40,2,FALSE),"") | P12: =IF(AND(ISNUMBER(SEARCH("adjust",F12)),OR(O12="warehouse_lost",O12="warehouse_damaged",O12="carrier_damaged",O12="transit_lost")),"yes","no") | Q12: =IF(P12="yes",IF(N12<>"",N12,MAX(0,-H12)),0)
A13: 2026-03-27 | B13: X0TH0010 | C13: B0TH010KX | D13: TH-BREKNI-10 | E13: Bread Knife 10in | F13: Receipts | G13: FBA15TH77096 | H13: 420 | I13: MDW2 | J13: SELLABLE | L13: US | M13: 0 | N13: 0 | O13: =IFERROR(VLOOKUP(K13,'Reason codes'!$A$2:$B$40,2,FALSE),"") | P13: =IF(AND(ISNUMBER(SEARCH("adjust",F13)),OR(O13="warehouse_lost",O13="warehouse_damaged",O13="carrier_damaged",O13="transit_lost")),"yes","no") | Q13: =IF(P13="yes",IF(N13<>"",N13,MAX(0,-H13)),0)
... A27: 2026-05-13 | B27: X0TH0024 | C27: B0TH024KX | D27: TH-KITTOW-24 | E27: Kitchen Towels Linen 4pk | F27: Receipts | G27: FBA15TH77252 | H27: 510 | I27: PHX7 | J27: SELLABLE | L27: US | M27: 0 | N27: 0 | O27: =IFERROR(VLOOKUP(K27,'Reason codes'!$A$2:$B$40,2,FALSE),"") | P27: =IF(AND(ISNUMBER(SEARCH("adjust",F27)),OR(O27="warehouse_lost",O27="warehouse_damaged",O27="carrier_damaged",O27="transit_lost")),"yes","no") | Q27: =IF(P27="yes",IF(N27<>"",N27,MAX(0,-H27)),0)
A28: 2026-05-15 | B28: X0TH0003 | C28: B0TH003KX | D28: TH-ENADUT-03 | E28: Enamel Dutch Oven 5qt | F28: Adjustments | G28: ADJ-77029 | H28: -4 | I28: MDW2 | J28: SELLABLE | K28: N | L28: US | M28: 4 | O28: =IFERROR(VLOOKUP(K28,'Reason codes'!$A$2:$B$40,2,FALSE),"") | P28: =IF(AND(ISNUMBER(SEARCH("adjust",F28)),OR(O28="warehouse_lost",O28="warehouse_damaged",O28="carrier_damaged",O28="transit_lost")),"yes","no") | Q28: =IF(P28="yes",IF(N28<>"",N28,MAX(0,-H28)),0)
A29: 2026-05-18 | B29: X0TH0001 | C29: B0TH001KX | D29: TH-CASIRO-01 | E29: Cast Iron Skillet 10in | F29: Adjustments | G29: ADJ-77002 | H29: -3 | I29: PHX7 | J29: SELLABLE | K29: N | L29: US | M29: 0 | N29: 3 | O29: =IFERROR(VLOOKUP(K29,'Reason codes'!$A$2:$B$40,2,FALSE),"") | P29: =IF(AND(ISNUMBER(SEARCH("adjust",F29)),OR(O29="warehouse_lost",O29="warehouse_damaged",O29="carrier_damaged",O29="transit_lost")),"yes","no") | Q29: =IF(P29="yes",IF(N29<>"",N29,MAX(0,-H29)),0)
A30: 2026-05-20 | B30: X0TH0005 | C30: B0TH005KX | D30: TH-BAMCUT-05 | E30: Bamboo Cutting Board L | F30: Adjustments | G30: ADJ-77050 | H30: -2 | I30: DFW6 | J30: SELLABLE | K30: N | L30: US | M30: 2 | O30: =IFERROR(VLOOKUP(K30,'Reason codes'!$A$2:$B$40,2,FALSE),"") | P30: =IF(AND(ISNUMBER(SEARCH("adjust",F30)),OR(O30="warehouse_lost",O30="warehouse_damaged",O30="carrier_damaged",O30="transit_lost")),"yes","no") | Q30: =IF(P30="yes",IF(N30<>"",N30,MAX(0,-H30)),0)
A31: 2026-05-20 | B31: X0TH0009 | C31: B0TH009KX | D31: TH-PARKNI-09 | E31: Paring Knife 3.5in | F31: Adjustments | G31: ADJ-77089 | H31: -2 | I31: MDW2 | J31: SELLABLE | K31: N | L31: US | M31: 0 | N31: 2 | O31: =IFERROR(VLOOKUP(K31,'Reason codes'!$A$2:$B$40,2,FALSE),"") | P31: =IF(AND(ISNUMBER(SEARCH("adjust",F31)),OR(O31="warehouse_lost",O31="warehouse_damaged",O31="carrier_damaged",O31="transit_lost")),"yes","no") | Q31: =IF(P31="yes",IF(N31<>"",N31,MAX(0,-H31)),0)
A32: 2026-05-21 | B32: X0TH0004 | C32: B0TH004KX | D32: TH-CARSTE-04 | E32: Carbon Steel Wok | F32: Receipts | G32: FBA15TH77035 | H32: 450 | I32: LAX9 | J32: SELLABLE | L32: US | M32: 0 | N32: 0 | O32: =IFERROR(VLOOKUP(K32,'Reason codes'!$A$2:$B$40,2,FALSE),"") | P32: =IF(AND(ISNUMBER(SEARCH("adjust",F32)),OR(O32="warehouse_lost",O32="warehouse_damaged",O32="carrier_damaged",O32="transit_lost")),"yes","no") | Q32: =IF(P32="yes",IF(N32<>"",N32,MAX(0,-H32)),0)
A33: 2026-05-23 | B33: X0TH0008 | C33: B0TH008KX | D33: TH-CHEKNI-08 | E33: Chef Knife 8in | F33: Receipts | G33: FBA15TH77075 | H33: 675 | I33: ONT8 | J33: SELLABLE | L33: US | M33: 0 | N33: 0 | O33: =IFERROR(VLOOKUP(K33,'Reason codes'!$A$2:$B$40,2,FALSE),"") | P33: =IF(AND(ISNUMBER(SEARCH("adjust",F33)),OR(O33="warehouse_lost",O33="warehouse_damaged",O33="carrier_damaged",O33="transit_lost")),"yes","no") | Q33: =IF(P33="yes",IF(N33<>"",N33,MAX(0,-H33)),0)
A34: 2026-05-25 | B34: X0TH0006 | C34: B0TH006KX | D34: TH-BAMCUT-06 | E34: Bamboo Cutting Board M | F34: Adjustments | G34: ADJ-77058 | H34: -7 | I34: PHX7 | J34: SELLABLE | K34: N | L34: US | M34: 0 | N34: 7 | O34: =IFERROR(VLOOKUP(K34,'Reason codes'!$A$2:$B$40,2,FALSE),"") | P34: =IF(AND(ISNUMBER(SEARCH("adjust",F34)),OR(O34="warehouse_lost",O34="warehouse_damaged",O34="carrier_damaged",O34="transit_lost")),"yes","no") | Q34: =IF(P34="yes",IF(N34<>"",N34,MAX(0,-H34)),0)
A35: 2026-05-26 | B35: X0TH0015 | C35: B0TH015KX | D35: TH-SALCEL-15 | E35: Salt Cellar Acacia | F35: Adjustments | G35: ADJ-77163 | H35: -8 | I35: MDW2 | J35: SELLABLE | K35: N | L35: US | M35: 0 | N35: 8 | O35: =IFERROR(VLOOKUP(K35,'Reason codes'!$A$2:$B$40,2,FALSE),"") | P35: =IF(AND(ISNUMBER(SEARCH("adjust",F35)),OR(O35="warehouse_lost",O35="warehouse_damaged",O35="carrier_damaged",O35="transit_lost")),"yes","no") | Q35: =IF(P35="yes",IF(N35<>"",N35,MAX(0,-H35)),0)
A36: 2026-05-27 | B36: X0TH0010 | C36: B0TH010KX | D36: TH-BREKNI-10 | E36: Bread Knife 10in | F36: Adjustments | G36: ADJ-77099 | H36: -5 | I36: ONT8 | J36: SELLABLE | K36: N | L36: US | M36: 5 | O36: =IFERROR(VLOOKUP(K36,'Reason codes'!$A$2:$B$40,2,FALSE),"") | P36: =IF(AND(ISNUMBER(SEARCH("adjust",F36)),OR(O36="warehouse_lost",O36="warehouse_damaged",O36="carrier_damaged",O36="transit_lost")),"yes","no") | Q36: =IF(P36="yes",IF(N36<>"",N36,MAX(0,-H36)),0)
A37: 2026-05-30 | B37: X0TH0011 | C37: B0TH011KX | D37: TH-KNISHA-11 | E37: Knife Sharpener Whetstone | F37: Adjustments | G37: ADJ-77113 | H37: -3 | I37: LAX9 | J37: SELLABLE | K37: N | L37: US | M37: 0 | N37: 3 | O37: =IFERROR(VLOOKUP(K37,'Reason codes'!$A$2:$B$40,2,FALSE),"") | P37: =IF(AND(ISNUMBER(SEARCH("adjust",F37)),OR(O37="warehouse_lost",O37="warehouse_damaged",O37="carrier_damaged",O37="transit_lost")),"yes","no") | Q37: =IF(P37="yes",IF(N37<>"",N37,MAX(0,-H37)),0)
A38: 2026-05-30 | B38: X0TH0014 | C38: B0TH014KX | D38: TH-MEACUP-14 | E38: Measuring Cups Steel | F38: Adjustments | G38: ADJ-77150 | H38: -8 | I38: LAX9 | J38: SELLABLE | K38: N | L38: US | M38: 0 | N38: 8 | O38: =IFERROR(VLOOKUP(K38,'Reason codes'!$A$2:$B$40,2,FALSE),"") | P38: =IF(AND(ISNUMBER(SEARCH("adjust",F38)),OR(O38="warehouse_lost",O38="warehouse_damaged",O38="carrier_damaged",O38="transit_lost")),"yes","no") | Q38: =IF(P38="yes",IF(N38<>"",N38,MAX(0,-H38)),0)
A39: 2026-06-01 | B39: X0TH0008 | C39: B0TH008KX | D39: TH-CHEKNI-08 | E39: Chef Knife 8in | F39: Adjustments | G39: ADJ-77080 | H39: -4 | I39: LAX9 | J39: SELLABLE | K39: N | L39: US | M39: 0 | N39: 4 | O39: =IFERROR(VLOOKUP(K39,'Reason codes'!$A$2:$B$40,2,FALSE),"") | P39: =IF(AND(ISNUMBER(SEARCH("adjust",F39)),OR(O39="warehouse_lost",O39="warehouse_damaged",O39="carrier_damaged",O39="transit_lost")),"yes","no") | Q39: =IF(P39="yes",IF(N39<>"",N39,MAX(0,-H39)),0)
A40: 2026-06-01 | B40: X0TH0010 | C40: B0TH010KX | D40: TH-BREKNI-10 | E40: Bread Knife 10in | F40: Receipts | G40: FBA15TH77097 | H40: 420 | I40: MDW2 | J40: SELLABLE | L40: US | M40: 0 | N40: 0 | O40: =IFERROR(VLOOKUP(K40,'Reason codes'!$A$2:$B$40,2,FALSE),"") | P40: =IF(AND(ISNUMBER(SEARCH("adjust",F40)),OR(O40="warehouse_lost",O40="warehouse_damaged",O40="carrier_damaged",O40="transit_lost")),"yes","no") | Q40: =IF(P40="yes",IF(N40<>"",N40,MAX(0,-H40)),0)
A41: 2026-06-03 | B41: X0TH0007 | C41: B0TH007KX | D41: TH-WALSER-07 | E41: Walnut Serving Tray | F41: Receipts | G41: FBA15TH77065 | H41: 285 | I41: LAX9 | J41: SELLABLE | L41: US | M41: 0 | N41: 0 | O41: =IFERROR(VLOOKUP(K41,'Reason codes'!$A$2:$B$40,2,FALSE),"") | P41: =IF(AND(ISNUMBER(SEARCH("adjust",F41)),OR(O41="warehouse_lost",O41="warehouse_damaged",O41="carrier_damaged",O41="transit_lost")),"yes","no") | Q41: =IF(P41="yes",IF(N41<>"",N41,MAX(0,-H41)),0)
A42: 2026-06-03 | B42: X0TH0024 | C42: B0TH024KX | D42: TH-KITTOW-24 | E42: Kitchen Towels Linen 4pk | F42: Receipts | G42: FBA15TH77251 | H42: 510 | I42: DFW6 | J42: SELLABLE | L42: US | M42: 0 | N42: 0 | O42: =IFERROR(VLOOKUP(K42,'Reason codes'!$A$2:$B$40,2,FALSE),"") | P42: =IF(AND(ISNUMBER(SEARCH("adjust",F42)),OR(O42="warehouse_lost",O42="warehouse_damaged",O42="carrier_damaged",O42="transit_lost")),"yes","no") | Q42: =IF(P42="yes",IF(N42<>"",N42,MAX(0,-H42)),0)
A43: 2026-06-04 | B43: X0TH0016 | C43: B0TH016KX | D43: TH-PEPMIL-16 | E43: Pepper Mill Walnut | F43: Adjustments | G43: ADJ-77173 | H43: -7 | I43: DFW6 | J43: SELLABLE | K43: N | L43: US | M43: 7 | O43: =IFERROR(VLOOKUP(K43,'Reason codes'!$A$2:$B$40,2,FALSE),"") | P43: =IF(AND(ISNUMBER(SEARCH("adjust",F43)),OR(O43="warehouse_lost",O43="warehouse_damaged",O43="carrier_damaged",O43="transit_lost")),"yes","no") | Q43: =IF(P43="yes",IF(N43<>"",N43,MAX(0,-H43)),0)
A44: 2026-06-09 | B44: X0TH0007 | C44: B0TH007KX | D44: TH-WALSER-07 | E44: Walnut Serving Tray | F44: Adjustments | G44: ADJ-77070 | H44: -6 | I44: MDW2 | J44: SELLABLE | K44: N | L44: US | M44: 6 | O44: =IFERROR(VLOOKUP(K44,'Reason codes'!$A$2:$B$40,2,FALSE),"") | P44: =IF(AND(ISNUMBER(SEARCH("adjust",F44)),OR(O44="warehouse_lost",O44="warehouse_damaged",O44="carrier_damaged",O44="transit_lost")),"yes","no") | Q44: =IF(P44="yes",IF(N44<>"",N44,MAX(0,-H44)),0)
A45: 2026-06-09 | B45: X0TH0019 | C45: B0TH019KX | D45: TH-COFCAN-19 | E45: Coffee Canister Airtight | F45: Adjustments | G45: ADJ-77202 | H45: -4 | I45: MDW2 | J45: SELLABLE | K45: N | L45: US | M45: 4 | O45: =IFERROR(VLOOKUP(K45,'Reason codes'!$A$2:$B$40,2,FALSE),"") | P45: =IF(AND(ISNUMBER(SEARCH("adjust",F45)),OR(O45="warehouse_lost",O45="warehouse_damaged",O45="carrier_damaged",O45="transit_lost")),"yes","no") | Q45: =IF(P45="yes",IF(N45<>"",N45,MAX(0,-H45)),0)
A46: 2026-06-10 | B46: X0TH0020 | C46: B0TH020KX | D46: TH-TEAINF-20 | E46: Tea Infuser Mug | F46: Receipts | G46: FBA15TH77208 | H46: 570 | I46: MDW2 | J46: SELLABLE | L46: US | M46: 0 | N46: 0 | O46: =IFERROR(VLOOKUP(K46,'Reason codes'!$A$2:$B$40,2,FALSE),"") | P46: =IF(AND(ISNUMBER(SEARCH("adjust",F46)),OR(O46="warehouse_lost",O46="warehouse_damaged",O46="carrier_damaged",O46="transit_lost")),"yes","no") | Q46: =IF(P46="yes",IF(N46<>"",N46,MAX(0,-H46)),0)
A47: 2026-06-15 | B47: X0TH0009 | C47: B0TH009KX | D47: TH-PARKNI-09 | E47: Paring Knife 3.5in | F47: Receipts | G47: FBA15TH77086 | H47: 915 | I47: ONT8 | J47: SELLABLE | L47: US | M47: 0 | N47: 0 | O47: =IFERROR(VLOOKUP(K47,'Reason codes'!$A$2:$B$40,2,FALSE),"") | P47: =IF(AND(ISNUMBER(SEARCH("adjust",F47)),OR(O47="warehouse_lost",O47="warehouse_damaged",O47="carrier_damaged",O47="transit_lost")),"yes","no") | Q47: =IF(P47="yes",IF(N47<>"",N47,MAX(0,-H47)),0)
A48: 2026-06-15 | B48: X0TH0022 | C48: B0TH022KX | D48: TH-OVEMIT-22 | E48: Oven Mitts Aramid Pair | F48: Adjustments | G48: ADJ-77235 | H48: -6 | I48: DFW6 | J48: SELLABLE | K48: N | L48: US | M48: 0 | N48: 6 | O48: =IFERROR(VLOOKUP(K48,'Reason codes'!$A$2:$B$40,2,FALSE),"") | P48: =IF(AND(ISNUMBER(SEARCH("adjust",F48)),OR(O48="warehouse_lost",O48="warehouse_damaged",O48="carrier_damaged",O48="transit_lost")),"yes","no") | Q48: =IF(P48="yes",IF(N48<>"",N48,MAX(0,-H48)),0)
A49: 2026-06-18 | B49: X0TH0019 | C49: B0TH019KX | D49: TH-COFCAN-19 | E49: Coffee Canister Airtight | F49: Receipts | G49: FBA15TH77196 | H49: 645 | I49: ONT8 | J49: SELLABLE | L49: US | M49: 0 | N49: 0 | O49: =IFERROR(VLOOKUP(K49,'Reason codes'!$A$2:$B$40,2,FALSE),"") | P49: =IF(AND(ISNUMBER(SEARCH("adjust",F49)),OR(O49="warehouse_lost",O49="warehouse_damaged",O49="carrier_damaged",O49="transit_lost")),"yes","no") | Q49: =IF(P49="yes",IF(N49<>"",N49,MAX(0,-H49)),0)
A50: 2026-06-20 | B50: X0TH0004 | C50: B0TH004KX | D50: TH-CARSTE-04 | E50: Carbon Steel Wok | F50: Adjustments | G50: ADJ-77039 | H50: -4 | I50: LAX9 | J50: SELLABLE | K50: N | L50: US | M50: 0 | N50: 4 | O50: =IFERROR(VLOOKUP(K50,'Reason codes'!$A$2:$B$40,2,FALSE),"") | P50: =IF(AND(ISNUMBER(SEARCH("adjust",F50)),OR(O50="warehouse_lost",O50="warehouse_damaged",O50="carrier_damaged",O50="transit_lost")),"yes","no") | Q50: =IF(P50="yes",IF(N50<>"",N50,MAX(0,-H50)),0)
A51: 2026-06-20 | B51: X0TH0020 | C51: B0TH020KX | D51: TH-TEAINF-20 | E51: Tea Infuser Mug | F51: Adjustments | G51: ADJ-77212 | H51: -4 | I51: LAX9 | J51: SELLABLE | K51: N | L51: US | M51: 4 | O51: =IFERROR(VLOOKUP(K51,'Reason codes'!$A$2:$B$40,2,FALSE),"") | P51: =IF(AND(ISNUMBER(SEARCH("adjust",F51)),OR(O51="warehouse_lost",O51="warehouse_damaged",O51="carrier_damaged",O51="transit_lost")),"yes","no") | Q51: =IF(P51="yes",IF(N51<>"",N51,MAX(0,-H51)),0)
A52: 2026-06-22 | B52: X0TH0024 | C52: B0TH024KX | D52: TH-KITTOW-24 | E52: Kitchen Towels Linen 4pk | F52: Adjustments | G52: ADJ-77256 | H52: -6 | I52: LAX9 | J52: SELLABLE | K52: N | L52: US | M52: 6 | O52: =IFERROR(VLOOKUP(K52,'Reason codes'!$A$2:$B$40,2,FALSE),"") | P52: =IF(AND(ISNUMBER(SEARCH("adjust",F52)),OR(O52="warehouse_lost",O52="warehouse_damaged",O52="carrier_damaged",O52="transit_lost")),"yes","no") | Q52: =IF(P52="yes",IF(N52<>"",N52,MAX(0,-H52)),0)
A53: 2026-06-25 | B53: X0TH0017 | C53: B0TH017KX | D53: TH-FREPRE-17 | E53: French Press 34oz | F53: Receipts | G53: FBA15TH77178 | H53: 585 | I53: LAX9 | J53: SELLABLE | L53: US | M53: 0 | N53: 0 | O53: =IFERROR(VLOOKUP(K53,'Reason codes'!$A$2:$B$40,2,FALSE),"") | P53: =IF(AND(ISNUMBER(SEARCH("adjust",F53)),OR(O53="warehouse_lost",O53="warehouse_damaged",O53="carrier_damaged",O53="transit_lost")),"yes","no") | Q53: =IF(P53="yes",IF(N53<>"",N53,MAX(0,-H53)),0)
...

Sheet Returns
A1: return-date | B1: order-id | C1: sku | D1: asin | E1: fnsku | F1: product-name | G1: quantity | H1: fulfillment-center-id | I1: detailed-disposition | J1: reason | K1: status | L1: Claimable (helper)
A2: 2026-05-25 | B2: 111-4000215-7071290 | C2: TH-CASIRO-01 | D2: B0TH001KX | E2: X0TH0001 | F2: Cast Iron Skillet 10in | G2: 1 | H2: ONT8 | I2: DAMAGED | J2: ORDERED_WRONG_ITEM | K2: Unit not returned to inventory | L2: =IF(AND(OR(I2="DAMAGED",I2="CARRIER_DAMAGED"),ISERROR(SEARCH("reimburs",K2))),"yes","no")
A3: 2026-05-26 | B3: 111-4006547-6808666 | C3: TH-SILSPA-13 | D3: B0TH013KX | E3: X0TH0013 | F3: Silicone Spatula Set | G3: 1 | H3: MDW2 | I3: SELLABLE | J3: NOT_AS_DESCRIBED | K3: Unit returned to inventory | L3: =IF(AND(OR(I3="DAMAGED",I3="CARRIER_DAMAGED"),ISERROR(SEARCH("reimburs",K3))),"yes","no")
A4: 2026-05-27 | B4: 111-4007866-6847779 | C4: TH-PEPMIL-16 | D4: B0TH016KX | E4: X0TH0016 | F4: Pepper Mill Walnut | G4: 1 | H4: MDW2 | I4: CUSTOMER_DAMAGED | J4: NOT_AS_DESCRIBED | K4: Unit not returned to inventory | L4: =IF(AND(OR(I4="DAMAGED",I4="CARRIER_DAMAGED"),ISERROR(SEARCH("reimburs",K4))),"yes","no")
A5: 2026-05-28 | B5: 111-4001074-3177903 | C5: TH-CASIRO-02 | D5: B0TH002KX | E5: X0TH0002 | F5: Cast Iron Skillet 12in | G5: 1 | H5: DFW6 | I5: CARRIER_DAMAGED | J5: ORDERED_WRONG_ITEM | K5: Unit not returned to inventory | L5: =IF(AND(OR(I5="DAMAGED",I5="CARRIER_DAMAGED"),ISERROR(SEARCH("reimburs",K5))),"yes","no")
A6: 2026-05-28 | B6: 111-4006090-3906751 | C6: TH-STAMIX-12 | D6: B0TH012KX | E6: X0TH0012 | F6: Stainless Mixing Bowls 5pc | G6: 1 | H6: ONT8 | I6: DEFECTIVE | J6: NOT_AS_DESCRIBED | K6: Unit not returned to inventory | L6: =IF(AND(OR(I6="DAMAGED",I6="CARRIER_DAMAGED"),ISERROR(SEARCH("reimburs",K6))),"yes","no")
A7: 2026-05-28 | B7: 111-4011691-1549916 | C7: TH-KITTOW-24 | D7: B0TH024KX | E7: X0TH0024 | F7: Kitchen Towels Linen 4pk | G7: 1 | H7: PHX7 | I7: DAMAGED | J7: UNWANTED_ITEM | K7: Unit not returned to inventory | L7: =IF(AND(OR(I7="DAMAGED",I7="CARRIER_DAMAGED"),ISERROR(SEARCH("reimburs",K7))),"yes","no")
A8: 2026-05-29 | B8: 111-4000397-3921245 | C8: TH-CASIRO-01 | D8: B0TH001KX | E8: X0TH0001 | F8: Cast Iron Skillet 10in | G8: 1 | H8: PHX7 | I8: SELLABLE | J8: DEFECTIVE | K8: Unit returned to inventory | L8: =IF(AND(OR(I8="DAMAGED",I8="CARRIER_DAMAGED"),ISERROR(SEARCH("reimburs",K8))),"yes","no")
A9: 2026-05-30 | B9: 111-4000290-1596218 | C9: TH-CASIRO-01 | D9: B0TH001KX | E9: X0TH0001 | F9: Cast Iron Skillet 10in | G9: 1 | H9: MDW2 | I9: DEFECTIVE | J9: UNWANTED_ITEM | K9: Unit not returned to inventory | L9: =IF(AND(OR(I9="DAMAGED",I9="CARRIER_DAMAGED"),ISERROR(SEARCH("reimburs",K9))),"yes","no")
A10: 2026-05-31 | B10: 111-4000484-5296207 | C10: TH-CASIRO-01 | D10: B0TH001KX | E10: X0TH0001 | F10: Cast Iron Skillet 10in | G10: 1 | H10: MDW2 | I10: DAMAGED | J10: UNWANTED_ITEM | K10: Unit not returned to inventory | L10: =IF(AND(OR(I10="DAMAGED",I10="CARRIER_DAMAGED"),ISERROR(SEARCH("reimburs",K10))),"yes","no")
A11: 2026-05-31 | B11: 111-4004114-9710250 | C11: TH-PARKNI-09 | D11: B0TH009KX | E11: X0TH0009 | F11: Paring Knife 3.5in | G11: 1 | H11: MDW2 | I11: SELLABLE | J11: UNWANTED_ITEM | K11: Unit returned to inventory | L11: =IF(AND(OR(I11="DAMAGED",I11="CARRIER_DAMAGED"),ISERROR(SEARCH("reimburs",K11))),"yes","no")
A12: 2026-05-31 | B12: 111-4005020-9298239 | C12: TH-KNISHA-11 | D12: B0TH011KX | E12: X0TH0011 | F12: Knife Sharpener Whetstone | G12: 1 | H12: ONT8 | I12: SELLABLE | J12: UNWANTED_ITEM | K12: Unit returned to inventory | L12: =IF(AND(OR(I12="DAMAGED",I12="CARRIER_DAMAGED"),ISERROR(SEARCH("reimburs",K12))),"yes","no")
A13: 2026-05-31 | B13: 111-4006766-2952585 | C13: TH-MEACUP-14 | D13: B0TH014KX | E13: X0TH0014 | F13: Measuring Cups Steel | G13: 1 | H13: LAX9 | I13: SELLABLE | J13: NOT_AS_DESCRIBED | K13: Unit returned to inventory | L13: =IF(AND(OR(I13="DAMAGED",I13="CARRIER_DAMAGED"),ISERROR(SEARCH("reimburs",K13))),"yes","no")
... A125: 2026-08-29 | B125: 111-4009157-6843329 | C125: TH-COFCAN-19 | D125: B0TH019KX | E125: X0TH0019 | F125: Coffee Canister Airtight | G125: 1 | H125: PHX7 | I125: DAMAGED | J125: ORDERED_WRONG_ITEM | K125: Unit not returned to inventory | L125: =IF(AND(OR(I125="DAMAGED",I125="CARRIER_DAMAGED"),ISERROR(SEARCH("reimburs",K125))),"yes","no")

Sheet Reimbursements
A1: approval-date | B1: reimbursement-id | C1: case-id | D1: amazon-order-id | E1: reason | F1: sku | G1: fnsku | H1: asin | I1: amount-per-unit | J1: amount-total | K1: quantity-reimbursed-cash | L1: quantity-reimbursed-inventory | M1: quantity-reimbursed-total | N1: original-reimbursement-type | O1: Cash share (helper)
A2: 2026-06-14 | B2: RM-77074 | E2: Damaged_Warehouse | F2: TH-WALSER-07 | G2: X0TH0007 | H2: B0TH007KX | I2: 13.1 | J2: 26.2 | K2: 2 | L2: 0 | M2: 2 | O2: =IF(M2>0,IF(K2<>"",K2,M2)/M2,0)
A3: 2026-06-24 | B3: RM-77084 | E3: Lost_Warehouse | F3: TH-CHEKNI-08 | G3: X0TH0008 | H3: B0TH008KX | I3: 16.6 | J3: 49.8 | K3: 3 | L3: 0 | M3: 3 | O3: =IF(M3>0,IF(K3<>"",K3,M3)/M3,0)
A4: 2026-06-30 | B4: RM-77064 | E4: Damaged_Warehouse | F4: TH-BAMCUT-06 | G4: X0TH0006 | H4: B0TH006KX | I4: 5.5 | J4: 0 | K4: 0 | L4: 3 | M4: 3 | O4: =IF(M4>0,IF(K4<>"",K4,M4)/M4,0)
A5: 2026-06-30 | B5: RM-77250 | E5: Damaged_Warehouse | F5: TH-TRICOR-23 | G5: X0TH0023 | H5: B0TH023KX | I5: 2.6 | J5: 7.8 | K5: 3 | L5: 0 | M5: 3 | O5: =IF(M5>0,IF(K5<>"",K5,M5)/M5,0)
A6: 2026-07-05 | B6: RM-77095 | E6: Lost_Warehouse | F6: TH-PARKNI-09 | G6: X0TH0009 | H6: B0TH009KX | I6: 4.8 | J6: 14.4 | K6: 3 | L6: 0 | M6: 3 | O6: =IF(M6>0,IF(K6<>"",K6,M6)/M6,0)
A7: 2026-07-15 | B7: RM-77122 | E7: Lost_Warehouse | F7: TH-KNISHA-11 | G7: X0TH0011 | H7: B0TH011KX | I7: 6.5 | J7: 6.5 | K7: 1 | L7: 0 | M7: 1 | O7: =IF(M7>0,IF(K7<>"",K7,M7)/M7,0)
A8: 2026-07-26 | B8: RM-77186 | E8: Damaged_Warehouse | F8: TH-FREPRE-17 | G8: X0TH0017 | H8: B0TH017KX | I8: 9 | J8: 27 | K8: 3 | L8: 0 | M8: 3 | O8: =IF(M8>0,IF(K8<>"",K8,M8)/M8,0)
A9: 2026-07-27 | B9: RM-77023 | E9: Lost_Warehouse | F9: TH-CASIRO-02 | G9: X0TH0002 | H9: B0TH002KX | I9: 16.1 | J9: 32.2 | K9: 2 | L9: 0 | M9: 2 | O9: =IF(M9>0,IF(K9<>"",K9,M9)/M9,0)
A10: 2026-08-08 | B10: RM-77045 | E10: Lost_Warehouse | F10: TH-CARSTE-04 | G10: X0TH0004 | H10: B0TH004KX | I10: 16.1 | J10: 32.2 | K10: 2 | L10: 0 | M10: 2 | O10: =IF(M10>0,IF(K10<>"",K10,M10)/M10,0)
A11: 2026-08-11 | B11: RM-77144 | E11: Lost_Warehouse | F11: TH-SILSPA-13 | G11: X0TH0013 | H11: B0TH013KX | I11: 3.3 | J11: 0 | K11: 0 | L11: 3 | M11: 3 | O11: =IF(M11>0,IF(K11<>"",K11,M11)/M11,0)
A12: 2026-08-20 | B12: RM-77264 | E12: Reversal | F12: TH-CARSTE-04 | G12: X0TH0004 | H12: B0TH004KX | I12: -16.1 | J12: -32.2 | K12: 2 | L12: 0 | M12: 2 | N12: Reversal | O12: =IF(M12>0,IF(K12<>"",K12,M12)/M12,0)
A13: 2026-08-23 | B13: RM-77167 | E13: Damaged_Warehouse | F13: TH-SALCEL-15 | G13: X0TH0015 | H13: B0TH015KX | I13: 4.1 | J13: 8.2 | K13: 2 | L13: 0 | M13: 2 | O13: =IF(M13>0,IF(K13<>"",K13,M13)/M13,0)

Sheet Refunds
A1: date/time | B1: type | C1: order id | D1: sku | E1: quantity | F1: product sales | G1: total | H1: Age in days (helper) | I1: Units returned (helper) | J1: Short (helper)
A2: 2026-05-08T20:00:00 | B2: Refund | C2: 111-4001167-4531939 | D2: TH-CASIRO-02 | E2: 1 | F2: -46.34 | G2: -40.78 | H2: =IFERROR(Windows!$B$2-DATEVALUE(LEFT(A2,10)),"") | I2: =SUMIFS(Returns!$G:$G,Returns!$B:$B,C2) | J2: =MAX(0,ABS(E2)-I2)
A3: 2026-05-11T16:00:00 | B3: Refund | C3: 111-4006638-6018624 | D3: TH-SILSPA-13 | E3: 1 | F3: -15.44 | G3: -13.59 | H3: =IFERROR(Windows!$B$2-DATEVALUE(LEFT(A3,10)),"") | I3: =SUMIFS(Returns!$G:$G,Returns!$B:$B,C3) | J3: =MAX(0,ABS(E3)-I3)
A4: 2026-05-12T14:00:00 | B4: Refund | C4: 111-4004228-2926992 | D4: TH-PARKNI-09 | E4: 1 | F4: -18.42 | G4: -16.21 | H4: =IFERROR(Windows!$B$2-DATEVALUE(LEFT(A4,10)),"") | I4: =SUMIFS(Returns!$G:$G,Returns!$B:$B,C4) | J4: =MAX(0,ABS(E4)-I4)
A5: 2026-05-15T01:00:00 | B5: Refund | C5: 111-4008814-6418098 | D5: TH-POUOVE-18 | E5: 1 | F5: -44.28 | G5: -38.97 | H5: =IFERROR(Windows!$B$2-DATEVALUE(LEFT(A5,10)),"") | I5: =SUMIFS(Returns!$G:$G,Returns!$B:$B,C5) | J5: =MAX(0,ABS(E5)-I5)
A6: 2026-05-21T11:00:00 | B6: Refund | C6: 111-4006547-6808666 | D6: TH-SILSPA-13 | E6: 1 | F6: -15.44 | G6: -13.59 | H6: =IFERROR(Windows!$B$2-DATEVALUE(LEFT(A6,10)),"") | I6: =SUMIFS(Returns!$G:$G,Returns!$B:$B,C6) | J6: =MAX(0,ABS(E6)-I6)
A7: 2026-05-22T22:00:00 | B7: Refund | C7: 111-4000215-7071290 | D7: TH-CASIRO-01 | E7: 1 | F7: -36.04 | G7: -31.72 | H7: =IFERROR(Windows!$B$2-DATEVALUE(LEFT(A7,10)),"") | I7: =SUMIFS(Returns!$G:$G,Returns!$B:$B,C7) | J7: =MAX(0,ABS(E7)-I7)
A8: 2026-05-24T07:00:00 | B8: Refund | C8: 111-4001074-3177903 | D8: TH-CASIRO-02 | E8: 1 | F8: -46.34 | G8: -40.78 | H8: =IFERROR(Windows!$B$2-DATEVALUE(LEFT(A8,10)),"") | I8: =SUMIFS(Returns!$G:$G,Returns!$B:$B,C8) | J8: =MAX(0,ABS(E8)-I8)
A9: 2026-05-24T10:00:00 | B9: Refund | C9: 111-4011691-1549916 | D9: TH-KITTOW-24 | E9: 1 | F9: -24.99 | G9: -21.99 | H9: =IFERROR(Windows!$B$2-DATEVALUE(LEFT(A9,10)),"") | I9: =SUMIFS(Returns!$G:$G,Returns!$B:$B,C9) | J9: =MAX(0,ABS(E9)-I9)
A10: 2026-05-24T19:00:00 | B10: Refund | C10: 111-4011334-2057147 | D10: TH-TRICOR-23 | E10: 1 | F10: -12.6 | G10: -11.09 | H10: =IFERROR(Windows!$B$2-DATEVALUE(LEFT(A10,10)),"") | I10: =SUMIFS(Returns!$G:$G,Returns!$B:$B,C10) | J10: =MAX(0,ABS(E10)-I10)
A11: 2026-05-25T07:00:00 | B11: Refund | C11: 111-4000397-3921245 | D11: TH-CASIRO-01 | E11: 1 | F11: -36.04 | G11: -31.72 | H11: =IFERROR(Windows!$B$2-DATEVALUE(LEFT(A11,10)),"") | I11: =SUMIFS(Returns!$G:$G,Returns!$B:$B,C11) | J11: =MAX(0,ABS(E11)-I11)
A12: 2026-05-25T08:00:00 | B12: Refund | C12: 111-4007866-6847779 | D12: TH-PEPMIL-16 | E12: 1 | F12: -33.98 | G12: -29.9 | H12: =IFERROR(Windows!$B$2-DATEVALUE(LEFT(A12,10)),"") | I12: =SUMIFS(Returns!$G:$G,Returns!$B:$B,C12) | J12: =MAX(0,ABS(E12)-I12)
A13: 2026-05-26T14:00:00 | B13: Refund | C13: 111-4006090-3906751 | D13: TH-STAMIX-12 | E13: 1 | F13: -38.1 | G13: -33.53 | H13: =IFERROR(Windows!$B$2-DATEVALUE(LEFT(A13,10)),"") | I13: =SUMIFS(Returns!$G:$G,Returns!$B:$B,C13) | J13: =MAX(0,ABS(E13)-I13)
... A149: 2026-08-27T15:00:00 | B149: Refund | C149: 111-4009157-6843329 | D149: TH-COFCAN-19 | E149: 1 | F149: -22.99 | G149: -20.23 | H149: =IFERROR(Windows!$B$2-DATEVALUE(LEFT(A149,10)),"") | I149: =SUMIFS(Returns!$G:$G,Returns!$B:$B,C149) | J149: =MAX(0,ABS(E149)-I149)

Sheet Claims
A1: Claim type | B1: SKU | C1: Event date | D1: Units | E1: Order id (refunds) | F1: Unit value | G1: Value | H1: Eligible from | I1: Deadline | J1: Days left | K1: Status | L1: P(approve) | M1: Expected value | N1: Value basis
A2: warehouse_lost | B2: TH-APRWAX-21 | C2: 46213 | D2: 21 | F2: =IFERROR(VLOOKUP(B2,COGS!$A$2:$G$25,7,FALSE),"") | G2: =IF(F2="","",D2*F2) | H2: =C2+VLOOKUP(A2,Windows!$A$24:$C$30,2,FALSE) | I2: =C2+VLOOKUP(A2,Windows!$A$24:$C$30,3,FALSE) | J2: =I2-Windows!$B$2 | K2: =IF(Windows!$B$2>I2,"expired",IF(Windows!$B$2<H2,"not_yet_eligible",IF(J2<=Windows!$B$9,"expiring","open"))) | L2: =VLOOKUP(A2,Windows!$A$15:$B$21,2,FALSE) | M2: =IF(G2="","",G2*L2) | N2: landed cost on file
A3: warehouse_lost | B3: TH-STAMIX-12 | C3: 46213 | D3: 18 | F3: =IFERROR(VLOOKUP(B3,COGS!$A$2:$G$25,7,FALSE),"") | G3: =IF(F3="","",D3*F3) | H3: =C3+VLOOKUP(A3,Windows!$A$24:$C$30,2,FALSE) | I3: =C3+VLOOKUP(A3,Windows!$A$24:$C$30,3,FALSE) | J3: =I3-Windows!$B$2 | K3: =IF(Windows!$B$2>I3,"expired",IF(Windows!$B$2<H3,"not_yet_eligible",IF(J3<=Windows!$B$9,"expiring","open"))) | L3: =VLOOKUP(A3,Windows!$A$15:$B$21,2,FALSE) | M3: =IF(G3="","",G3*L3) | N3: landed cost on file
A4: carrier_damaged | B4: TH-ENADUT-03 | C4: 46213 | D4: 8 | F4: =IFERROR(VLOOKUP(B4,COGS!$A$2:$G$25,7,FALSE),"") | G4: =IF(F4="","",D4*F4) | H4: =C4+VLOOKUP(A4,Windows!$A$24:$C$30,2,FALSE) | I4: =C4+VLOOKUP(A4,Windows!$A$24:$C$30,3,FALSE) | J4: =I4-Windows!$B$2 | K4: =IF(Windows!$B$2>I4,"expired",IF(Windows!$B$2<H4,"not_yet_eligible",IF(J4<=Windows!$B$9,"expiring","open"))) | L4: =VLOOKUP(A4,Windows!$A$15:$B$21,2,FALSE) | M4: =IF(G4="","",G4*L4) | N4: landed cost on file
A5: transit_lost | B5: TH-CASIRO-02 | C5: 46215 | D5: 11 | F5: =IFERROR(VLOOKUP(B5,COGS!$A$2:$G$25,7,FALSE),"") | G5: =IF(F5="","",D5*F5) | H5: =C5+VLOOKUP(A5,Windows!$A$24:$C$30,2,FALSE) | I5: =C5+VLOOKUP(A5,Windows!$A$24:$C$30,3,FALSE) | J5: =I5-Windows!$B$2 | K5: =IF(Windows!$B$2>I5,"expired",IF(Windows!$B$2<H5,"not_yet_eligible",IF(J5<=Windows!$B$9,"expiring","open"))) | L5: =VLOOKUP(A5,Windows!$A$15:$B$21,2,FALSE) | M5: =IF(G5="","",G5*L5) | N5: landed cost on file
A6: warehouse_lost | B6: TH-FREPRE-17 | C6: 46214 | D6: 16 | F6: =IFERROR(VLOOKUP(B6,COGS!$A$2:$G$25,7,FALSE),"") | G6: =IF(F6="","",D6*F6) | H6: =C6+VLOOKUP(A6,Windows!$A$24:$C$30,2,FALSE) | I6: =C6+VLOOKUP(A6,Windows!$A$24:$C$30,3,FALSE) | J6: =I6-Windows!$B$2 | K6: =IF(Windows!$B$2>I6,"expired",IF(Windows!$B$2<H6,"not_yet_eligible",IF(J6<=Windows!$B$9,"expiring","open"))) | L6: =VLOOKUP(A6,Windows!$A$15:$B$21,2,FALSE) | M6: =IF(G6="","",G6*L6) | N6: landed cost on file
A7: warehouse_lost | B7: TH-KITTOW-24 | C7: 46218 | D7: 20 | F7: =IFERROR(VLOOKUP(B7,COGS!$A$2:$G$25,7,FALSE),"") | G7: =IF(F7="","",D7*F7) | H7: =C7+VLOOKUP(A7,Windows!$A$24:$C$30,2,FALSE) | I7: =C7+VLOOKUP(A7,Windows!$A$24:$C$30,3,FALSE) | J7: =I7-Windows!$B$2 | K7: =IF(Windows!$B$2>I7,"expired",IF(Windows!$B$2<H7,"not_yet_eligible",IF(J7<=Windows!$B$9,"expiring","open"))) | L7: =VLOOKUP(A7,Windows!$A$15:$B$21,2,FALSE) | M7: =IF(G7="","",G7*L7) | N7: landed cost on file
A8: warehouse_lost | B8: TH-PARKNI-09 | C8: 46216 | D8: 25 | F8: =IFERROR(VLOOKUP(B8,COGS!$A$2:$G$25,7,FALSE),"") | G8: =IF(F8="","",D8*F8) | H8: =C8+VLOOKUP(A8,Windows!$A$24:$C$30,2,FALSE) | I8: =C8+VLOOKUP(A8,Windows!$A$24:$C$30,3,FALSE) | J8: =I8-Windows!$B$2 | K8: =IF(Windows!$B$2>I8,"expired",IF(Windows!$B$2<H8,"not_yet_eligible",IF(J8<=Windows!$B$9,"expiring","open"))) | L8: =VLOOKUP(A8,Windows!$A$15:$B$21,2,FALSE) | M8: =IF(G8="","",G8*L8) | N8: landed cost on file
A9: warehouse_lost | B9: TH-CHEKNI-08 | C9: 46217 | D9: 7 | F9: =IFERROR(VLOOKUP(B9,COGS!$A$2:$G$25,7,FALSE),"") | G9: =IF(F9="","",D9*F9) | H9: =C9+VLOOKUP(A9,Windows!$A$24:$C$30,2,FALSE) | I9: =C9+VLOOKUP(A9,Windows!$A$24:$C$30,3,FALSE) | J9: =I9-Windows!$B$2 | K9: =IF(Windows!$B$2>I9,"expired",IF(Windows!$B$2<H9,"not_yet_eligible",IF(J9<=Windows!$B$9,"expiring","open"))) | L9: =VLOOKUP(A9,Windows!$A$15:$B$21,2,FALSE) | M9: =IF(G9="","",G9*L9) | N9: landed cost on file
A10: warehouse_lost | B10: TH-COFCAN-19 | C10: 46214 | D10: 17 | F10: =IFERROR(VLOOKUP(B10,COGS!$A$2:$G$25,7,FALSE),"") | G10: =IF(F10="","",D10*F10) | H10: =C10+VLOOKUP(A10,Windows!$A$24:$C$30,2,FALSE) | I10: =C10+VLOOKUP(A10,Windows!$A$24:$C$30,3,FALSE) | J10: =I10-Windows!$B$2 | K10: =IF(Windows!$B$2>I10,"expired",IF(Windows!$B$2<H10,"not_yet_eligible",IF(J10<=Windows!$B$9,"expiring","open"))) | L10: =VLOOKUP(A10,Windows!$A$15:$B$21,2,FALSE) | M10: =IF(G10="","",G10*L10) | N10: landed cost on file
A11: carrier_damaged | B11: TH-PEPMIL-16 | C11: 46209 | D11: 13 | F11: =IFERROR(VLOOKUP(B11,COGS!$A$2:$G$25,7,FALSE),"") | G11: =IF(F11="","",D11*F11) | H11: =C11+VLOOKUP(A11,Windows!$A$24:$C$30,2,FALSE) | I11: =C11+VLOOKUP(A11,Windows!$A$24:$C$30,3,FALSE) | J11: =I11-Windows!$B$2 | K11: =IF(Windows!$B$2>I11,"expired",IF(Windows!$B$2<H11,"not_yet_eligible",IF(J11<=Windows!$B$9,"expiring","open"))) | L11: =VLOOKUP(A11,Windows!$A$15:$B$21,2,FALSE) | M11: =IF(G11="","",G11*L11) | N11: landed cost on file
A12: carrier_damaged | B12: TH-WALSER-07 | C12: 46208 | D12: 9 | F12: =IFERROR(VLOOKUP(B12,COGS!$A$2:$G$25,7,FALSE),"") | G12: =IF(F12="","",D12*F12) | H12: =C12+VLOOKUP(A12,Windows!$A$24:$C$30,2,FALSE) | I12: =C12+VLOOKUP(A12,Windows!$A$24:$C$30,3,FALSE) | J12: =I12-Windows!$B$2 | K12: =IF(Windows!$B$2>I12,"expired",IF(Windows!$B$2<H12,"not_yet_eligible",IF(J12<=Windows!$B$9,"expiring","open"))) | L12: =VLOOKUP(A12,Windows!$A$15:$B$21,2,FALSE) | M12: =IF(G12="","",G12*L12) | N12: landed cost on file
A13: transit_lost | B13: TH-CARSTE-04 | C13: 46211 | D13: 7 | F13: =IFERROR(VLOOKUP(B13,COGS!$A$2:$G$25,7,FALSE),"") | G13: =IF(F13="","",D13*F13) | H13: =C13+VLOOKUP(A13,Windows!$A$24:$C$30,2,FALSE) | I13: =C13+VLOOKUP(A13,Windows!$A$24:$C$30,3,FALSE) | J13: =I13-Windows!$B$2 | K13: =IF(Windows!$B$2>I13,"expired",IF(Windows!$B$2<H13,"not_yet_eligible",IF(J13<=Windows!$B$9,"expiring","open"))) | L13: =VLOOKUP(A13,Windows!$A$15:$B$21,2,FALSE) | M13: =IF(G13="","",G13*L13) | N13: landed cost on file
... A23: carrier_damaged | B23: TH-BAMCUT-05 | C23: 46213 | D23: 6 | F23: =IFERROR(VLOOKUP(B23,COGS!$A$2:$G$25,7,FALSE),"") | G23: =IF(F23="","",D23*F23) | H23: =C23+VLOOKUP(A23,Windows!$A$24:$C$30,2,FALSE) | I23: =C23+VLOOKUP(A23,Windows!$A$24:$C$30,3,FALSE) | J23: =I23-Windows!$B$2 | K23: =IF(Windows!$B$2>I23,"expired",IF(Windows!$B$2<H23,"not_yet_eligible",IF(J23<=Windows!$B$9,"expiring","open"))) | L23: =VLOOKUP(A23,Windows!$A$15:$B$21,2,FALSE) | M23: =IF(G23="","",G23*L23) | N23: landed cost on file
A24: refund_no_return | B24: TH-CASIRO-02 | C24: 46150 | D24: 1 | E24: 111-4001167-4531939 | F24: 46.34 | G24: =IF(F24="","",D24*F24) | H24: =C24+VLOOKUP(A24,Windows!$A$24:$C$30,2,FALSE) | I24: =C24+VLOOKUP(A24,Windows!$A$24:$C$30,3,FALSE) | J24: =I24-Windows!$B$2 | K24: =IF(Windows!$B$2>I24,"expired",IF(Windows!$B$2<H24,"not_yet_eligible",IF(J24<=Windows!$B$9,"expiring","open"))) | L24: =VLOOKUP(A24,Windows!$A$15:$B$21,2,FALSE) | M24: =IF(G24="","",G24*L24) | N24: refunded amount per unit — Amazon reimburses at its determined value, so this is the ceiling
A25: refund_no_return | B25: TH-POUOVE-18 | C25: 46157 | D25: 1 | E25: 111-4008814-6418098 | F25: 44.28 | G25: =IF(F25="","",D25*F25) | H25: =C25+VLOOKUP(A25,Windows!$A$24:$C$30,2,FALSE) | I25: =C25+VLOOKUP(A25,Windows!$A$24:$C$30,3,FALSE) | J25: =I25-Windows!$B$2 | K25: =IF(Windows!$B$2>I25,"expired",IF(Windows!$B$2<H25,"not_yet_eligible",IF(J25<=Windows!$B$9,"expiring","open"))) | L25: =VLOOKUP(A25,Windows!$A$15:$B$21,2,FALSE) | M25: =IF(G25="","",G25*L25) | N25: refunded amount per unit — Amazon reimburses at its determined value, so this is the ceiling
A26: carrier_damaged | B26: TH-PARKNI-09 | C26: 46214 | D26: 9 | F26: =IFERROR(VLOOKUP(B26,COGS!$A$2:$G$25,7,FALSE),"") | G26: =IF(F26="","",D26*F26) | H26: =C26+VLOOKUP(A26,Windows!$A$24:$C$30,2,FALSE) | I26: =C26+VLOOKUP(A26,Windows!$A$24:$C$30,3,FALSE) | J26: =I26-Windows!$B$2 | K26: =IF(Windows!$B$2>I26,"expired",IF(Windows!$B$2<H26,"not_yet_eligible",IF(J26<=Windows!$B$9,"expiring","open"))) | L26: =VLOOKUP(A26,Windows!$A$15:$B$21,2,FALSE) | M26: =IF(G26="","",G26*L26) | N26: landed cost on file
A27: warehouse_lost | B27: TH-TRICOR-23 | C27: 46214 | D27: 8 | F27: =IFERROR(VLOOKUP(B27,COGS!$A$2:$G$25,7,FALSE),"") | G27: =IF(F27="","",D27*F27) | H27: =C27+VLOOKUP(A27,Windows!$A$24:$C$30,2,FALSE) | I27: =C27+VLOOKUP(A27,Windows!$A$24:$C$30,3,FALSE) | J27: =I27-Windows!$B$2 | K27: =IF(Windows!$B$2>I27,"expired",IF(Windows!$B$2<H27,"not_yet_eligible",IF(J27<=Windows!$B$9,"expiring","open"))) | L27: =VLOOKUP(A27,Windows!$A$15:$B$21,2,FALSE) | M27: =IF(G27="","",G27*L27) | N27: landed cost on file
A28: carrier_damaged | B28: TH-TRICOR-23 | C28: 46213 | D28: 8 | F28: =IFERROR(VLOOKUP(B28,COGS!$A$2:$G$25,7,FALSE),"") | G28: =IF(F28="","",D28*F28) | H28: =C28+VLOOKUP(A28,Windows!$A$24:$C$30,2,FALSE) | I28: =C28+VLOOKUP(A28,Windows!$A$24:$C$30,3,FALSE) | J28: =I28-Windows!$B$2 | K28: =IF(Windows!$B$2>I28,"expired",IF(Windows!$B$2<H28,"not_yet_eligible",IF(J28<=Windows!$B$9,"expiring","open"))) | L28: =VLOOKUP(A28,Windows!$A$15:$B$21,2,FALSE) | M28: =IF(G28="","",G28*L28) | N28: landed cost on file
A29: carrier_damaged | B29: TH-KNISHA-11 | C29: 46210 | D29: 3 | F29: =IFERROR(VLOOKUP(B29,COGS!$A$2:$G$25,7,FALSE),"") | G29: =IF(F29="","",D29*F29) | H29: =C29+VLOOKUP(A29,Windows!$A$24:$C$30,2,FALSE) | I29: =C29+VLOOKUP(A29,Windows!$A$24:$C$30,3,FALSE) | J29: =I29-Windows!$B$2 | K29: =IF(Windows!$B$2>I29,"expired",IF(Windows!$B$2<H29,"not_yet_eligible",IF(J29<=Windows!$B$9,"expiring","open"))) | L29: =VLOOKUP(A29,Windows!$A$15:$B$21,2,FALSE) | M29: =IF(G29="","",G29*L29) | N29: landed cost on file
A30: carrier_damaged | B30: TH-OVEMIT-22 | C30: 46209 | D30: 4 | F30: =IFERROR(VLOOKUP(B30,COGS!$A$2:$G$25,7,FALSE),"") | G30: =IF(F30="","",D30*F30) | H30: =C30+VLOOKUP(A30,Windows!$A$24:$C$30,2,FALSE) | I30: =C30+VLOOKUP(A30,Windows!$A$24:$C$30,3,FALSE) | J30: =I30-Windows!$B$2 | K30: =IF(Windows!$B$2>I30,"expired",IF(Windows!$B$2<H30,"not_yet_eligible",IF(J30<=Windows!$B$9,"expiring","open"))) | L30: =VLOOKUP(A30,Windows!$A$15:$B$21,2,FALSE) | M30: =IF(G30="","",G30*L30) | N30: landed cost on file
A31: refund_no_return | B31: TH-PARKNI-09 | C31: 46154 | D31: 1 | E31: 111-4004228-2926992 | F31: 18.42 | G31: =IF(F31="","",D31*F31) | H31: =C31+VLOOKUP(A31,Windows!$A$24:$C$30,2,FALSE) | I31: =C31+VLOOKUP(A31,Windows!$A$24:$C$30,3,FALSE) | J31: =I31-Windows!$B$2 | K31: =IF(Windows!$B$2>I31,"expired",IF(Windows!$B$2<H31,"not_yet_eligible",IF(J31<=Windows!$B$9,"expiring","open"))) | L31: =VLOOKUP(A31,Windows!$A$15:$B$21,2,FALSE) | M31: =IF(G31="","",G31*L31) | N31: refunded amount per unit — Amazon reimburses at its determined value, so this is the ceiling
A32: refund_no_return | B32: TH-SILSPA-13 | C32: 46153 | D32: 1 | E32: 111-4006638-6018624 | F32: 15.44 | G32: =IF(F32="","",D32*F32) | H32: =C32+VLOOKUP(A32,Windows!$A$24:$C$30,2,FALSE) | I32: =C32+VLOOKUP(A32,Windows!$A$24:$C$30,3,FALSE) | J32: =I32-Windows!$B$2 | K32: =IF(Windows!$B$2>I32,"expired",IF(Windows!$B$2<H32,"not_yet_eligible",IF(J32<=Windows!$B$9,"expiring","open"))) | L32: =VLOOKUP(A32,Windows!$A$15:$B$21,2,FALSE) | M32: =IF(G32="","",G32*L32) | N32: refunded amount per unit — Amazon reimburses at its determined value, so this is the ceiling
A33: damaged_return | B33: TH-WALSER-07 | C33: 46219 | D33: 1 | E33: 111-4003317-9770649 | F33: =IFERROR(VLOOKUP(B33,COGS!$A$2:$G$25,7,FALSE),"") | G33: =IF(F33="","",D33*F33) | H33: =C33+VLOOKUP(A33,Windows!$A$24:$C$30,2,FALSE) | I33: =C33+VLOOKUP(A33,Windows!$A$24:$C$30,3,FALSE) | J33: =I33-Windows!$B$2 | K33: =IF(Windows!$B$2>I33,"expired",IF(Windows!$B$2<H33,"not_yet_eligible",IF(J33<=Windows!$B$9,"expiring","open"))) | L33: =VLOOKUP(A33,Windows!$A$15:$B$21,2,FALSE) | M33: =IF(G33="","",G33*L33) | N33: landed cost on file
A34: damaged_return | B34: TH-CASIRO-01 | C34: 46209 | D34: 1 | E34: 111-4000172-1485759 | F34: =IFERROR(VLOOKUP(B34,COGS!$A$2:$G$25,7,FALSE),"") | G34: =IF(F34="","",D34*F34) | H34: =C34+VLOOKUP(A34,Windows!$A$24:$C$30,2,FALSE) | I34: =C34+VLOOKUP(A34,Windows!$A$24:$C$30,3,FALSE) | J34: =I34-Windows!$B$2 | K34: =IF(Windows!$B$2>I34,"expired",IF(Windows!$B$2<H34,"not_yet_eligible",IF(J34<=Windows!$B$9,"expiring","open"))) | L34: =VLOOKUP(A34,Windows!$A$15:$B$21,2,FALSE) | M34: =IF(G34="","",G34*L34) | N34: landed cost on file
A35: damaged_return | B35: TH-APRWAX-21 | C35: 46220 | D35: 1 | E35: 111-4010212-9353804 | F35: =IFERROR(VLOOKUP(B35,COGS!$A$2:$G$25,7,FALSE),"") | G35: =IF(F35="","",D35*F35) | H35: =C35+VLOOKUP(A35,Windows!$A$24:$C$30,2,FALSE) | I35: =C35+VLOOKUP(A35,Windows!$A$24:$C$30,3,FALSE) | J35: =I35-Windows!$B$2 | K35: =IF(Windows!$B$2>I35,"expired",IF(Windows!$B$2<H35,"not_yet_eligible",IF(J35<=Windows!$B$9,"expiring","open"))) | L35: =VLOOKUP(A35,Windows!$A$15:$B$21,2,FALSE) | M35: =IF(G35="","",G35*L35) | N35: landed cost on file
A36: damaged_return | B36: TH-COFCAN-19 | C36: 46212 | D36: 1 | E36: 111-4009121-3689668 | F36: =IFERROR(VLOOKUP(B36,COGS!$A$2:$G$25,7,FALSE),"") | G36: =IF(F36="","",D36*F36) | H36: =C36+VLOOKUP(A36,Windows!$A$24:$C$30,2,FALSE) | I36: =C36+VLOOKUP(A36,Windows!$A$24:$C$30,3,FALSE) | J36: =I36-Windows!$B$2 | K36: =IF(Windows!$B$2>I36,"expired",IF(Windows!$B$2<H36,"not_yet_eligible",IF(J36<=Windows!$B$9,"expiring","open"))) | L36: =VLOOKUP(A36,Windows!$A$15:$B$21,2,FALSE) | M36: =IF(G36="","",G36*L36) | N36: landed cost on file
A37: damaged_return | B37: TH-COFCAN-19 | C37: 46209 | D37: 1 | E37: 111-4009221-3909542 | F37: =IFERROR(VLOOKUP(B37,COGS!$A$2:$G$25,7,FALSE),"") | G37: =IF(F37="","",D37*F37) | H37: =C37+VLOOKUP(A37,Windows!$A$24:$C$30,2,FALSE) | I37: =C37+VLOOKUP(A37,Windows!$A$24:$C$30,3,FALSE) | J37: =I37-Windows!$B$2 | K37: =IF(Windows!$B$2>I37,"expired",IF(Windows!$B$2<H37,"not_yet_eligible",IF(J37<=Windows!$B$9,"expiring","open"))) | L37: =VLOOKUP(A37,Windows!$A$15:$B$21,2,FALSE) | M37: =IF(G37="","",G37*L37) | N37: landed cost on file
A38: damaged_return | B38: TH-OVEMIT-22 | C38: 46216 | D38: 1 | E38: 111-4010585-7573195 | F38: =IFERROR(VLOOKUP(B38,COGS!$A$2:$G$25,7,FALSE),"") | G38: =IF(F38="","",D38*F38) | H38: =C38+VLOOKUP(A38,Windows!$A$24:$C$30,2,FALSE) | I38: =C38+VLOOKUP(A38,Windows!$A$24:$C$30,3,FALSE) | J38: =I38-Windows!$B$2 | K38: =IF(Windows!$B$2>I38,"expired",IF(Windows!$B$2<H38,"not_yet_eligible",IF(J38<=Windows!$B$9,"expiring","open"))) | L38: =VLOOKUP(A38,Windows!$A$15:$B$21,2,FALSE) | M38: =IF(G38="","",G38*L38) | N38: landed cost on file
A39: warehouse_lost | B39: TH-CARSTE-04 | C39: 46230 | D39: 18 | F39: =IFERROR(VLOOKUP(B39,COGS!$A$2:$G$25,7,FALSE),"") | G39: =IF(F39="","",D39*F39) | H39: =C39+VLOOKUP(A39,Windows!$A$24:$C$30,2,FALSE) | I39: =C39+VLOOKUP(A39,Windows!$A$24:$C$30,3,FALSE) | J39: =I39-Windows!$B$2 | K39: =IF(Windows!$B$2>I39,"expired",IF(Windows!$B$2<H39,"not_yet_eligible",IF(J39<=Windows!$B$9,"expiring","open"))) | L39: =VLOOKUP(A39,Windows!$A$15:$B$21,2,FALSE) | M39: =IF(G39="","",G39*L39) | N39: landed cost on file
A40: warehouse_lost | B40: TH-POUOVE-18 | C40: 46227 | D40: 18 | F40: =IFERROR(VLOOKUP(B40,COGS!$A$2:$G$25,7,FALSE),"") | G40: =IF(F40="","",D40*F40) | H40: =C40+VLOOKUP(A40,Windows!$A$24:$C$30,2,FALSE) | I40: =C40+VLOOKUP(A40,Windows!$A$24:$C$30,3,FALSE) | J40: =I40-Windows!$B$2 | K40: =IF(Windows!$B$2>I40,"expired",IF(Windows!$B$2<H40,"not_yet_eligible",IF(J40<=Windows!$B$9,"expiring","open"))) | L40: =VLOOKUP(A40,Windows!$A$15:$B$21,2,FALSE) | M40: =IF(G40="","",G40*L40) | N40: landed cost on file
A41: warehouse_lost | B41: TH-ENADUT-03 | C41: 46230 | D41: 8 | F41: =IFERROR(VLOOKUP(B41,COGS!$A$2:$G$25,7,FALSE),"") | G41: =IF(F41="","",D41*F41) | H41: =C41+VLOOKUP(A41,Windows!$A$24:$C$30,2,FALSE) | I41: =C41+VLOOKUP(A41,Windows!$A$24:$C$30,3,FALSE) | J41: =I41-Windows!$B$2 | K41: =IF(Windows!$B$2>I41,"expired",IF(Windows!$B$2<H41,"not_yet_eligible",IF(J41<=Windows!$B$9,"expiring","open"))) | L41: =VLOOKUP(A41,Windows!$A$15:$B$21,2,FALSE) | M41: =IF(G41="","",G41*L41) | N41: landed cost on file
A42: warehouse_lost | B42: TH-PEPMIL-16 | C42: 46227 | D42: 18 | F42: =IFERROR(VLOOKUP(B42,COGS!$A$2:$G$25,7,FALSE),"") | G42: =IF(F42="","",D42*F42) | H42: =C42+VLOOKUP(A42,Windows!$A$24:$C$30,2,FALSE) | I42: =C42+VLOOKUP(A42,Windows!$A$24:$C$30,3,FALSE) | J42: =I42-Windows!$B$2 | K42: =IF(Windows!$B$2>I42,"expired",IF(Windows!$B$2<H42,"not_yet_eligible",IF(J42<=Windows!$B$9,"expiring","open"))) | L42: =VLOOKUP(A42,Windows!$A$15:$B$21,2,FALSE) | M42: =IF(G42="","",G42*L42) | N42: landed cost on file
A43: warehouse_lost | B43: TH-WALSER-07 | C43: 46226 | D43: 7 | F43: =IFERROR(VLOOKUP(B43,COGS!$A$2:$G$25,7,FALSE),"") | G43: =IF(F43="","",D43*F43) | H43: =C43+VLOOKUP(A43,Windows!$A$24:$C$30,2,FALSE) | I43: =C43+VLOOKUP(A43,Windows!$A$24:$C$30,3,FALSE) | J43: =I43-Windows!$B$2 | K43: =IF(Windows!$B$2>I43,"expired",IF(Windows!$B$2<H43,"not_yet_eligible",IF(J43<=Windows!$B$9,"expiring","open"))) | L43: =VLOOKUP(A43,Windows!$A$15:$B$21,2,FALSE) | M43: =IF(G43="","",G43*L43) | N43: landed cost on file
A44: warehouse_lost | B44: TH-BAMCUT-06 | C44: 46221 | D44: 15 | F44: =IFERROR(VLOOKUP(B44,COGS!$A$2:$G$25,7,FALSE),"") | G44: =IF(F44="","",D44*F44) | H44: =C44+VLOOKUP(A44,Windows!$A$24:$C$30,2,FALSE) | I44: =C44+VLOOKUP(A44,Windows!$A$24:$C$30,3,FALSE) | J44: =I44-Windows!$B$2 | K44: =IF(Windows!$B$2>I44,"expired",IF(Windows!$B$2<H44,"not_yet_eligible",IF(J44<=Windows!$B$9,"expiring","open"))) | L44: =VLOOKUP(A44,Windows!$A$15:$B$21,2,FALSE) | M44: =IF(G44="","",G44*L44) | N44: landed cost on file
A45: warehouse_lost | B45: TH-SALCEL-15 | C45: 46231 | D45: 18 | F45: =IFERROR(VLOOKUP(B45,COGS!$A$2:$G$25,7,FALSE),"") | G45: =IF(F45="","",D45*F45) | H45: =C45+VLOOKUP(A45,Windows!$A$24:$C$30,2,FALSE) | I45: =C45+VLOOKUP(A45,Windows!$A$24:$C$30,3,FALSE) | J45: =I45-Windows!$B$2 | K45: =IF(Windows!$B$2>I45,"expired",IF(Windows!$B$2<H45,"not_yet_eligible",IF(J45<=Windows!$B$9,"expiring","open"))) | L45: =VLOOKUP(A45,Windows!$A$15:$B$21,2,FALSE) | M45: =IF(G45="","",G45*L45) | N45: landed cost on file
A46: refund_no_return | B46: TH-CARSTE-04 | C46: 46188 | D46: 1 | E46: 111-4001943-4629004 | F46: 51.49 | G46: =IF(F46="","",D46*F46) | H46: =C46+VLOOKUP(A46,Windows!$A$24:$C$30,2,FALSE) | I46: =C46+VLOOKUP(A46,Windows!$A$24:$C$30,3,FALSE) | J46: =I46-Windows!$B$2 | K46: =IF(Windows!$B$2>I46,"expired",IF(Windows!$B$2<H46,"not_yet_eligible",IF(J46<=Windows!$B$9,"expiring","open"))) | L46: =VLOOKUP(A46,Windows!$A$15:$B$21,2,FALSE) | M46: =IF(G46="","",G46*L46) | N46: refunded amount per unit — Amazon reimburses at its determined value, so this is the ceiling
A47: refund_no_return | B47: TH-POUOVE-18 | C47: 46206 | D47: 1 | E47: 111-4008775-1999468 | F47: 44.28 | G47: =IF(F47="","",D47*F47) | H47: =C47+VLOOKUP(A47,Windows!$A$24:$C$30,2,FALSE) | I47: =C47+VLOOKUP(A47,Windows!$A$24:$C$30,3,FALSE) | J47: =I47-Windows!$B$2 | K47: =IF(Windows!$B$2>I47,"expired",IF(Windows!$B$2<H47,"not_yet_eligible",IF(J47<=Windows!$B$9,"expiring","open"))) | L47: =VLOOKUP(A47,Windows!$A$15:$B$21,2,FALSE) | M47: =IF(G47="","",G47*L47) | N47: refunded amount per unit — Amazon reimburses at its determined value, so this is the ceiling
A48: refund_no_return | B48: TH-WALSER-07 | C48: 46206 | D48: 1 | E48: 111-4003456-9226073 | F48: 37.82 | G48: =IF(F48="","",D48*F48) | H48: =C48+VLOOKUP(A48,Windows!$A$24:$C$30,2,FALSE) | I48: =C48+VLOOKUP(A48,Windows!$A$24:$C$30,3,FALSE) | J48: =I48-Windows!$B$2 | K48: =IF(Windows!$B$2>I48,"expired",IF(Windows!$B$2<H48,"not_yet_eligible",IF(J48<=Windows!$B$9,"expiring","open"))) | L48: =VLOOKUP(A48,Windows!$A$15:$B$21,2,FALSE) | M48: =IF(G48="","",G48*L48) | N48: refunded amount per unit — Amazon reimburses at its determined value, so this is the ceiling
A49: refund_no_return | B49: TH-CASIRO-01 | C49: 46197 | D49: 1 | E49: 111-4000554-9214500 | F49: 36.04 | G49: =IF(F49="","",D49*F49) | H49: =C49+VLOOKUP(A49,Windows!$A$24:$C$30,2,FALSE) | I49: =C49+VLOOKUP(A49,Windows!$A$24:$C$30,3,FALSE) | J49: =I49-Windows!$B$2 | K49: =IF(Windows!$B$2>I49,"expired",IF(Windows!$B$2<H49,"not_yet_eligible",IF(J49<=Windows!$B$9,"expiring","open"))) | L49: =VLOOKUP(A49,Windows!$A$15:$B$21,2,FALSE) | M49: =IF(G49="","",G49*L49) | N49: refunded amount per unit — Amazon reimburses at its determined value, so this is the ceiling
...

Sheet Filing log
A1: Claim row | B1: SKU | C1: Case id | D1: Filed on | E1: Amazon's answer | F1: Paid in cash | G1: Replaced in inventory (units) | H1: Paid on | I1: Notes
